<?xml version="1.0"?>

<!-- Definicion del robot -->
<robot name="op1_robot">

    <!-- Definicion del link de la base -->
    <link name="base_link">
        <inertial>
            <origin xyz="0 0 0.1" />
            <mass value="1000.0" />
            <inertia ixx="1.0" ixy="0.0" ixz="0.0"
            iyy="1.0" iyz="0.0" izz="1.0" />

        </inertial>

        <visual>
            <origin xyz="0 0 0.1" />
            <geometry>
                <box size="0.4 0.4 0.2" />
            </geometry>
            <material name="white"/>
        </visual>

        <collision>
            <origin xyz="0 0 0.1" />
            <geometry>
             <box size="0.4 0.4 0.2" />
            </geometry>
        </collision>

    </link>
    
    <!-- Definicion del color azul -->
    <material name="blue">
        <color rgba="0 0 0.8 1" />
    </material>

    <!-- Definicion del link que actua de cuerpo -->
    <link name="body_link">

        <inertial>
            <origin rpy="0 0 0" xyz="0 0 0.5" />
            <mass value="1.0" />
            <inertia ixx="1.0" ixy="0.0" ixz="0.0"
            iyy="0.0" iyz="0.0" izz="1.0" />

        </inertial>
        <visual>        
            <origin rpy="0 0 0" xyz="0 0 0.5" />
            <geometry>
                <box size="0.1 0.1 0.8" />
            </geometry>
            <material name="blue"/>
        </visual>

        <collision>
            <origin rpy="0 0 0" xyz="0 0 0.5" />
            <geometry>
             <box size="0.1 0.1 0.8" />
            </geometry>
        </collision>

    </link>

    <!-- Definicion del link de la parte superior -->
    <link name="top_link">

        <inertial>
            <origin rpy="0 0 0" xyz="0.2 0 0.1" />
            <mass value="1.0" />
            <inertia ixx="1.0" ixy="0.0" ixz="0.0"
            iyy="0.0" iyz="0.0" izz="1.0" />

        </inertial>
        <visual>        
            <origin rpy="0 0 0" xyz="0.2 0 0.1" />
            <geometry>
                <box size="0.4 0.1 0.1" />
            </geometry>
            <material name="blue"/>
        </visual>

        <collision>
            <origin rpy="0 0 0" xyz="0.2 0 0.1" />
            <geometry>
             <box size="0.4 0.1 0.1" />
            </geometry>
        </collision>

    </link>

    <!-- Definicion del joint entre la base y el cuerpo -->
    <joint name="base_to_body" type="revolute">
        <parent link="base_link" />
        <child link="body_link" />
        <dynamics damping="0.0" friction="0.00001" />
        <origin xyz="0.05 0 0.1" />
        <axis xyz="0 0 1" />

        <limit lower="-0.14" upper="0.14" effort="10.0" velocity="0.5" />
    </joint>

    <!-- Definicion del joint entre el cuerpo y la parte superior -->
    <joint name="body_to_top" type="revolute">
        <parent link="body_link" />
        <child link="top_link" />
        <dynamics damping="0.0" friction="0.01" />
        <origin xyz="0 0 0.8" />
        <axis xyz="0 0 1" />

        <limit lower="-3.14" upper="3.14" effort="10.0" velocity="0.5" />
    </joint>

</robot>